Workbook
Name Ampliación_de_capital_1: 'ANALISIS '!$L$8
Name año_fin_fianza: 'HIPOTESIS '!$F$40
Name años_amortiz_activ1: 'HIPOTESIS '!$F$52
Name años_amortiz_activ2: 'HIPOTESIS '!$F$55
Name años_amortiz_inv1: 'HIPOTESIS '!$F$44
Name años_amortiz_inv2: 'HIPOTESIS '!$F$47
Name años_subv_activ1: 'HIPOTESIS '!$F$53
Name años_subv_activ2: 'HIPOTESIS '!$F$56
Name años_subvencion1: 'HIPOTESIS '!$F$45
Name años_subvencion2: 'HIPOTESIS '!$F$48
Name carencia_p1: 'HIPOTESIS '!$E$66
Name carencia_p2: 'HIPOTESIS '!$E$67
Name carencia_prest_participa: 'ANALISIS '!$M$11
Name existencias_A: 'HIPOTESIS '!$P$131
Name existencias_B: 'HIPOTESIS '!$P$132
Name existencias_C: 'HIPOTESIS '!$P$133
Name final_amortiz_activ1: 'HIPOTESIS '!$K$52
Name final_amortiz_activ2: 'HIPOTESIS '!$K$55
Name final_inv1: 'HIPOTESIS '!$H$44
Name final_inv2: 'HIPOTESIS '!$H$47
Name final_p1: 'HIPOTESIS '!$G$66
Name final_p2: 'HIPOTESIS '!$G$67
Name final_prest_participa: 'ANALISIS '!$O$11
Name final_subv_activ1: 'HIPOTESIS '!$K$53
Name final_subv_activ2: 'HIPOTESIS '!$K$56
Name final_subv_inv1: 'HIPOTESIS '!$H$45
Name final_subv_inv2: 'HIPOTESIS '!$H$48
Name final_trabaj_activacion1: 'HIPOTESIS '!$H$52
Name final_trabaj_activacion2: 'HIPOTESIS '!$H$55
Name imp_activacion1: 'HIPOTESIS '!$C$52
Name imp_activacion2: 'HIPOTESIS '!$C$55
Name imp_inv1: 'HIPOTESIS '!$C$44
Name imp_inv2: 'HIPOTESIS '!$C$47
Name imp_mensual_trabajo_activ1: 'HIPOTESIS '!$I$52
Name imp_mensual_trabajo_activ2: 'HIPOTESIS '!$I$55
Name imp_p1: 'HIPOTESIS '!$D$66
Name imp_p2: 'HIPOTESIS '!$D$67
Name imp_subv_activ1: 'HIPOTESIS '!$C$53
Name imp_subv_activ2: 'HIPOTESIS '!$C$56
Name imp_subv_inv1: 'HIPOTESIS '!$C$45
Name imp_subv_inv2: 'HIPOTESIS '!$C$48
Name importe_fianza: 'HIPOTESIS '!$C$40
Name importe_prest_participa: 'ANALISIS '!$L$11
Name inicio_amortiz_activ1: 'HIPOTESIS '!$J$52
Name inicio_amortiz_activ2: 'HIPOTESIS '!$J$55
Name inicio_inv1: 'HIPOTESIS '!$G$44
Name inicio_inv2: 'HIPOTESIS '!$G$47
Name inicio_p1: 'HIPOTESIS '!$C$66
Name inicio_p2: 'HIPOTESIS '!$C$67
Name inicio_prest_participa: 'ANALISIS '!$K$11
Name inicio_subv_activ1: 'HIPOTESIS '!$J$53
Name inicio_subv_activ2: 'HIPOTESIS '!$J$56
Name inicio_subv_inv1: 'HIPOTESIS '!$G$45
Name inicio_subv_inv2: 'HIPOTESIS '!$G$48
Name inicio_trabaj_activacion1: 'HIPOTESIS '!$G$52
Name inicio_trabaj_activacion2: 'HIPOTESIS '!$G$55
Name interes_inicio_prest_participa: 'ANALISIS '!$P$11
Name interes_p1: 'HIPOTESIS '!$H$66
Name interes_p2: 'HIPOTESIS '!$H$67
Name interes_participativo_prest_participa: 'ANALISIS '!$Q$11

Sheet IDEA
A4: HOJA DE RUTA DEL PLAN ECONÓMICO FINANCIERO (PEF) CON TOOLBOARD CANVAS
B6: http://toolboardcanvas.com/ | K6: METODOLOGÍA TOOLBOARD CANVAS DE EMPRENDIMIENTO Y INNOVACIÓN Esta hoja de cálculo desarrollada mediante excel es la herramienta 8 de TOOLBOARD . Forma parte del libro "El Viaje del emprendedor: generación de iniciativas de emprendimiento y innovación con ToolBoard Canvas". Accede gratuitamente y si quieres saber más visita: http://toolboardcanvas.com/ o escribe al autor: jaumeteodoro@gmail.com Las hojas están inicialmente completadas con un ejemplo anónimo a sobrescribir.
B8: jaumeteodoro@gmail.com
B10: IDENTIFICACIÓN DEL PROYECTO
B11: Nombre del proyecto: | C11: Nombre_Proyecto | H11: Link: | I11: www.proyecto.com
B12: Integrantes del equipo: | C12: Nombre_apellido1; Nombre_Apellido2 | H12: Contacto: | I12: a@gmail.com
B13: Fecha: | C13: 1/1/00 | H13: Versión: | I13: 1.0
A16: Parte I: DESCRIPCIÓN DEL NEGOCIO
B20: A- PROBLEMA-SOLUCIÓN (problem -solution fit)
B64: B- MODELO DE NEGOCIO (Business Model)
B66: Parte derecha del Canvas (Cliente y estrategias de márquetin para capturar y retener los clientes)
B89: Parte izquierda del Canvas (organización y operaciones de explotación de la organización)
B117: C- PLANIFICACIÓN (Milestones)
B119: Los hitos de negocio son todos aquellas circunstancias esperadas que son relevantes cara a la elaboración del Plan Económico Financiero (PEF). Se trata de grandes objetivos que el equipo emprendedor asume en su lógica para progresar de la idea inicial a un proyecto empresarial real. Se situan en el eje temporal en un diagrama como el adjunto, a título de ejemplo, a partir de un nombre/ descriptor del hito, una fecha estimada, una métrica y un importe asociado a la consecución del hito.
B122: HITO | C122: DESCRIPTOR | D122: FECHA | F122: RECURSOS | H122: IMPORTE | J122: OBSERVACIONES
B123: 1 | C123: EQUIPO: Constitución del equipo de fundadores | D123: Año 0 /I | F123: Team Manifesto | H123: 1000 | J123: Fondos iniciales tipo FFF para empezar , pendientes de formalizar en el momento de la constitución de la empresa.
B124: 2 | C124: IDEA Y PROTOTIPO: Planteamiento, esbozo y primera validación de la idea con su modelo de negocio. | D124: Año 0 /I | F124: Prototipo conceptual | H124: -500 | J124: Desarrollo de la idea y inversión en la prototipo conceptual
B125: 3 | C125: PITCH DE LA IDEA: Cierre de una primera versión del Pitch a efectos de equipo y otros stakeholders. | D125: Año 0/ I | F125: Eventos de Pitch | H125: -500 | J125: Desarrollo del ToolBoard Canvas de inicio que muestra la idea y el modelo de negocio de partida. Orientado a equipo y programas de soporte a emprendedores. Canvas con acceso desde : www.Miro.com /proyecto
B126: 4 | C126: SOCIEDAD: Constitución de la Sociedad y primeras inversiones operativas en año 0. | D126: Año 0 / II | F126: Acto de constitución. Capital social | H126: 25000 | J126: Primeros fondos FFF aportados por los fundadores (se considera todo el año 0 como mes 0 del proyecto) y fondos seed capital (pequeños inversores, subvenciones y premios). Se llevan a cabo las primeras inversiones. Se incurre en los primeros gastos fijos y de personal (salarios de los fundadores y de otros integrantes del equipo). Es común que parte de los costes de personal relativos a los fundadores no se desembolsen hasta que exista actividad económica.
B127: 5 | C127: MVP: Validación en mercado real en una incubadora o aceleradora. Primeras ventas usuarios tempranos. | D127: Año 0 / II | F127: Realización y usuarios tempranos | H127: -10000 | J127: Validación con clientes en mercado real. Inversión en el MVP. Identificación de los early adopters.
B128: 6 | C128: PLAN ECONÓMICO FINANCIERO (PEF). A partir de los primeros resultados en mercado real se desarrolla un primer PEF | D128: Año 0 / II | F128: Personal propio y asesores | H128: 0 | J128: Realización del primer borrador del PEF a partir del modelo de negocio y las conclusiones del proceso de validación. Se trabaja con escenarios a fin de gestionar el dilema de la prudencia. En este momento es posible que la iniciativa ingrese en una incubadora o en un programa de aceleración
B129: 7 | C129: INVERSIONES INICIALES: Inversiones y trabajos para el propio activo indispensables para inicio de las operaciones | D129: Año 1 / I | F129: Personal propio y alianzas | H129: (mmmm) | J129: Actividad de inversiones de partida a la que se suma la investigación, desarrollo y innovación (I+D+i) que lleva a la creación de activos intangibles con recursos propios (trabajos para el propio activo en el PEF). Puede ser el caso de una patente industrial, un proceso de fabricación de un producto, un software y en general cualquier activo elaborado con recursos propios (desembolsados o pendientes de desembolsar) que la Startup va a rentabilizar a lo largo del tiempo.
B130: 8 | C130: INICIO OPERATIVO: Empieza el ciclo de ventas y la acción de márquetin con las primeras inversiones. | D130: Año I/I | F130: Clientes reales | H130: >0 | J130: Foco en ventas reales que validen y muestren la creación de valor. Uso de la métrica de negocio identificada en el PEF para medir objetivos, según tipo de industria: leads, usuarios, ventas, descargas, … En este momento se produce la incorporación de nuevo personal en nómina.
B131: 9 | C131: PITCH DE LA STARTUP: Nuevo Pitch con ToolBoard Canvas orientado a inversionistas de capital (angel capital) | D131: Año 1 /II | F131: Foros de inversión | H131: 0 | J131: Desarrollo completo con ToolBoard Canvas, incluyendo los resultados del MVP y el primer borrador del PEF.
B132: 10 | C132: AMPLIACIÓN DE CAPITAL : Momento en que se espera la entrada de inversores (Angel Capital) | D132: Año 2 y en adelante | F132: Según valoración de empresa y % de la propiedad a cambio | H132: 20% -30% de la propiedad | J132: Para la entrada de socios inversores de capital va ser necesario mostrar métricas de negocio con las que poder hacer una valoración de la startup. El emprendedor hace frente al dilema de la dilución buscando el mejor momento para dar entrada a inversores
B133: 11 | C133: ESCALABILIDAD: Nuevas inversiones a medida que se consiguen objetivos de ventas. Adaptación de la estructura (gastos fijos) según métricas de crecimiento y disponible. | D133: Año 2 y en adelante | F133: Proyectos de inversión | H133: n x 1.000 | J133: Incremento de la capacidad productiva, comercial y de gestión a partir de nuevos proyectos de inversión y ampliaciones de la estructura de la empresa. Puede tratarse de nuevos productos, servicios, funcionalidades o expansión en un nuevo mercado.
B134: 12 | C134: PUNTO MUERTO: Momento en que se provee alcanzar el punto de equilibrio | D134: Año 1 o 2 o en adelante | F134: EBT | H134: >0 | J134: El punto de equilibrio (Ingresos Totales = Gastos Totales) se calcula con la hoja de cálculo a partir de la proyección de la cuenta de resultados. El proyecto va a requerir un tiempo para alcanzar este umbral de rentabilidad. Durante este tiempo las métricas de crecimiento (ventas) son la referencia valorar el desarrollo del proyecto. A partir del umbral la métrica básica para medir el proyecto será la rentabilidad en EBT.
B135: 13 | C135: APALANCAMIENTO / CAPITAL INSTITUCIONAL: Captación de recursos financieros externos a partir de préstamos | D135: Año 3 y en adelante | F135: Préstamos bancarios | H135: (mmmm) | J135: Momento en que los datos de la empresa permiten su valoración y con ello obtener financiación externa. El objetivo es obtener la máxima eficiencia en cuanto a fondos propios buscando el máximo apalancamiento posible si la solvencia de la empresa y el tipo de interés del dinero lo permite.
B139: Diagrama de hitos:

Sheet HIPOTESIS 
B2: www.toolboardcanvas.com
A4: Parte II: HIPÓTESIS DE NEGOCIO
B6: FISCALIDAD (Taxes)
B8: FISCALIDAD | C8: #1 | D8: #2 | E8: # 3 | F8: OBSERVACIONES
B9: Impuesto de sociedades (IS) | C9: 0.25 | F9: Cada país tiene un tipo medio estimado. En este caso se estima un tipo medio del 25% para España.
B10: Impuesto del Valor Añadido (IVA) de las compras | C10: 0.21 | F10: Los tipos de IVA se pueden cambiar según normativa del impuesto en cada país. Por este motivo se puede modificar el dato de esta tabla, que por defecto es del 21%. La liquidación de IVA en esta hoja de cálculo se hace por meses. Todos los importes a entrar en hipótesis iniciales en adelante se entran sin IVA.
B11: Impuesto del Valor Añadido (IVA) de las ventas | C11: 0.21
B12: Impuesto del Valor Añadido (IVA) de las inversiones | C12: 0.21
B13: Seguro social régimen especial de autónomos | C13: 0.15 | D13: 0 | E13: 56640 | F13: El primer dato corresponde a lo que paga la empresa y el segundo a lo que paga el trabajador. El tercer dato corresponde al tope máximo a partir del cual ya no se paga más.
B14: Seguro social régimen general | C14: 0.33 | D14: 0.0647 | E14: 56640
B15: Retención RENTA a los trabajadores (IRPF) | C15: 0 | D15: 0.2 | E15: 0.4 | F15: Se hace un cálculo abreviado muy simple, solamente en 3 tramos (#1, #2 y #3) de forma que en cada tramo se indica un porcentaje de retención según sueldo bruto: . #1 en 0% para salario bruto menor a 15.000,#2 en 20% entre 15.000 y 90.000 y #3 en 40% por encima de 90.000). Si se desea se puede hacer el cálculo precisa accediendo a la web de hacienda una vez conocidos los trabajadores y sus características personales.
B19: º
A21: A. HIPÓTESIS SOBRE INVERSIONES (CAPEX)
B24: INVERSIONES DE INICIO (Año 0) | C24: IMPORTE | D24: %IVA | E24: IVA | F24: AÑOS AMORTIZA. | G24: MES ADQUISICIÓN | H24: MES FIN AMORTIZA. | I24: OBSERVACIONES
B25: Inmovilizado intangible
B26: Investigación y desarrollo | C26: 0 | D26: =IVA_inversiones -> 0.21 | E26: =C26*D26 -> 0 | F26: 5 | G26: 0 | H26: =F26*12+G26 -> 60
B27: Patentes y marcas | C27: 0 | D27: =IVA_inversiones -> 0.21 | E27: =C27*D27 -> 0 | F27: 10 | G27: 0 | H27: =F27*12+G27 -> 120
B28: Aplicaciones informáticas | C28: 0 | D28: =IVA_inversiones -> 0.21 | E28: =C28*D28 -> 0 | F28: 5 | G28: 0 | H28: =F28*12+G28 -> 60
B29: Otros inmovilizados intangibles | C29: 0 | D29: =IVA_inversiones -> 0.21 | E29: =C29*D29 -> 0 | F29: 5 | G29: 0 | H29: =F29*12+G29 -> 60
B30: Inmovilizado material
B31: Terrenos y construcciones | C31: 0 | D31: 0 | E31: =C31*D31 -> 0 | F31: 50 | G31: 0 | H31: =F31*12+G31 -> 600
B32: Instalaciones | C32: 0 | D32: =IVA_inversiones -> 0.21 | E32: =C32*D32 -> 0 | F32: 10 | G32: 0 | H32: =F32*12+G32 -> 120
B33: Maquinaria | C33: 0 | D33: =IVA_inversiones -> 0.21 | E33: =C33*D33 -> 0 | F33: 10 | G33: 0 | H33: =F33*12+G33 -> 120
B34: Equipos para procesos de información( EPIs) | C34: 0 | D34: =IVA_inversiones -> 0.21 | E34: =C34*D34 -> 0 | F34: 5 | G34: 0 | H34: =F34*12+G34 -> 60
B35: Mobiliario | C35: 0 | D35: =IVA_inversiones -> 0.21 | E35: =C35*D35 -> 0 | F35: 10 | G35: 0 | H35: =F35*12+G35 -> 120
B36: Vehículos | C36: 0 | D36: =IVA_inversiones -> 0.21 | E36: =C36*D36 -> 0 | F36: 10 | G36: 0 | H36: =F36*12+G36 -> 120
B37: Otros inmovilizados materiales | C37: 0 | D37: =IVA_inversiones -> 0.21 | E37: =C37*D37 -> 0 | F37: 5 | G37: 0 | H37: =F37*12+G37 -> 60
B38: Total inversiones al inicio | C38: =C26+C27+C28+C29+C31+C32+C33+C34+C35+C36+C37 -> 0 | E38: =SUM(E26:E37) -> 0
B39: Fianzas y depósitos | I39: Indicar aquí las inversiones de tipo finazas y depósitos necesarias para arrancar el proyecto (mes 0).
B40: Fianzas y depósitos a largo plazo | C40: 0 | F40: 5 | G40: 1
B42: PROYECTOS DE INVERSIÓN EN AÑOS POSTERIORES | C42: IMPORTE | D42: %IVA | E42: IVA | F42: AÑOS AMORTIZA. | G42: MES ADQUISICIÓN | H42: MES FIN AMORTIZA. | I42: OBSERVACIONES
B43: Detalle de la nueva inversión (1) | I43: Explicar aquí en que consiste el proyecto 1 y si existe una subención de capital
B44: Nuevo proyecto de inversión 1 | C44: 0 | D44: =IVA_inversiones -> 0.21 | E44: =imp_inv1*D44 -> 0 | F44: 1 | G44: 1 | H44: =inicio_inv1+años_amortiz_inv1*12 -> 13
B45: Subvención de capital por inversión (1) | C45: 0 | D45: 0 | F45: 1 | G45: 1 | H45: =H44 -> 13
B46: Detalle de la nueva inversión (2) | I46: Explicar aquí en que consiste el proyecto 2 y si existe una subvención de capital
B47: Nuevo proyecto de inversión 2 | C47: 0 | D47: =IVA_inversiones -> 0.21 | E47: =imp_inv2*D47 -> 0 | F47: 1 | G47: 1 | H47: =inicio_inv2+años_amortiz_inv2*12 -> 13
B48: Subvención de capital por inversión (2) | C48: 0 | D48: 0 | F48: =años_amortiz_inv2 -> 1 | G48: =inicio_inv2 -> 1 | H48: =H47 -> 13
B50: PROYECTOS DE TRABAJO PARA EL PROPIO ACTIVO / INMOVILIZADO INTANGIBLE | C50: IMPORTE | D50: %IVA | E50: IVA | F50: AÑOS AMORTIZA. | G50: MES INICIO PROYECTO | H50: MES FIN PROYECTO | I50: IMPORTE MEDIO MENSUAL | J50: MES INICIO AMORTIZA. | K50: MES FINAL AMORTIZA. | L50: OBSERVACIONES
B51: Detalle del proyecto de activación I+D+i (1) | L51: Explica aquí en que consiste el proyecto I+D+i de trabajo para el propio activo.
B52: Proyecto de trabajo para el propio activo 1 | C52: 0 | D52: 0 | E52: 0 | F52: 1 | G52: 1 | H52: 1 | I52: =imp_activacion1/(final_trabaj_activacion1-inicio_trabaj_activacion1+1) -> 0 | J52: =final_trabaj_activacion1+1 -> 2 | K52: =inicio_amortiz_activ1+años_amortiz_activ1*12 -> 14
...

Sheet C
A1: DETALLE DE CÁLCULOS A PARTIR DE LAS HIPÓTESIS
BN2: listas desplegables
B3: CUADRO DE AMORTIZACIONES MENSUALES DE LAS INVERSIONES EN ACTIVOS | C3: MESES
C4: 0 | D4: 1 | E4: 2 | F4: 3 | G4: 4 | H4: 5 | I4: 6 | J4: 7 | K4: 8 | L4: 9 | M4: 10 | N4: 11 | O4: 12 | P4: 13 | Q4: 14 | R4: 15 | S4: 16 | T4: 17 | U4: 18 | V4: 19 | W4: 20 | X4: 21 | Y4: 22 | Z4: 23 | AA4: 24 | AB4: 25 | AC4: 26 | AD4: 27 | AE4: 28 | AF4: 29 | AG4: 30 | AH4: 31 | AI4: 32 | AJ4: 33 | AK4: 34 | AL4: 35 | AM4: 36 | AN4: 37 | AO4: 38 | AP4: 39 | AQ4: 40 | AR4: 41 | AS4: 42 | AT4: 43 | AU4: 44 | AV4: 45 | AW4: 46 | AX4: 47 | AY4: 48 | AZ4: 49 | BA4: 50 | BB4: 51 | BC4: 52 | BD4: 53 | BE4: 54 | BF4: 55 | BG4: 56 | BH4: 57 | BI4: 58 | BJ4: 59 | BK4: 60 | BO4: 0 | BP4: 0
B5: Amortización inmobilizado intangible inicial | BO5: 1 | BP5: 1
B6: Investigación y desarrollo | C6: 0 | D6: =IF(D$4<=('HIPOTESIS '!$F26*12),'HIPOTESIS '!$C$26/('HIPOTESIS '!$F$26*12),0) -> 0 | E6: =IF(E$4<=('HIPOTESIS '!$F26*12),'HIPOTESIS '!$C$26/('HIPOTESIS '!$F$26*12),0) -> 0 | F6: =IF(F$4<=('HIPOTESIS '!$F26*12),'HIPOTESIS '!$C$26/('HIPOTESIS '!$F$26*12),0) -> 0 | G6: =IF(G$4<=('HIPOTESIS '!$F26*12),'HIPOTESIS '!$C$26/('HIPOTESIS '!$F$26*12),0) -> 0 | H6: =IF(H$4<=('HIPOTESIS '!$F26*12),'HIPOTESIS '!$C$26/('HIPOTESIS '!$F$26*12),0) -> 0 | I6: =IF(I$4<=('HIPOTESIS '!$F26*12),'HIPOTESIS '!$C$26/('HIPOTESIS '!$F$26*12),0) -> 0 | J6: =IF(J$4<=('HIPOTESIS '!$F26*12),'HIPOTESIS '!$C$26/('HIPOTESIS '!$F$26*12),0) -> 0 | K6: =IF(K$4<=('HIPOTESIS '!$F26*12),'HIPOTESIS '!$C$26/('HIPOTESIS '!$F$26*12),0) -> 0 | ... BK6: =IF(BK$4<=('HIPOTESIS '!$F26*12),'HIPOTESIS '!$C$26/('HIPOTESIS '!$F$26*12),0) -> 0 | BO6: 2 | BP6: 2
B7: Patentes y marcas | C7: 0 | D7: =IF(D$4<='HIPOTESIS '!$F27*12,'HIPOTESIS '!$C27/('HIPOTESIS '!$F27*12),0) -> 0 | E7: =IF(E$4<='HIPOTESIS '!$F27*12,'HIPOTESIS '!$C27/('HIPOTESIS '!$F27*12),0) -> 0 | F7: =IF(F$4<='HIPOTESIS '!$F27*12,'HIPOTESIS '!$C27/('HIPOTESIS '!$F27*12),0) -> 0 | G7: =IF(G$4<='HIPOTESIS '!$F27*12,'HIPOTESIS '!$C27/('HIPOTESIS '!$F27*12),0) -> 0 | H7: =IF(H$4<='HIPOTESIS '!$F27*12,'HIPOTESIS '!$C27/('HIPOTESIS '!$F27*12),0) -> 0 | I7: =IF(I$4<='HIPOTESIS '!$F27*12,'HIPOTESIS '!$C27/('HIPOTESIS '!$F27*12),0) -> 0 | J7: =IF(J$4<='HIPOTESIS '!$F27*12,'HIPOTESIS '!$C27/('HIPOTESIS '!$F27*12),0) -> 0 | K7: =IF(K$4<='HIPOTESIS '!$F27*12,'HIPOTESIS '!$C27/('HIPOTESIS '!$F27*12),0) -> 0 | ... BK7: =IF(BK$4<='HIPOTESIS '!$F27*12,'HIPOTESIS '!$C27/('HIPOTESIS '!$F27*12),0) -> 0 | BO7: 3 | BP7: 3
B8: Aplicaciones informáticas | C8: 0 | D8: =IF(D$4<='HIPOTESIS '!$F28*12,'HIPOTESIS '!$C28/('HIPOTESIS '!$F28*12),0) -> 0 | E8: =IF(E$4<='HIPOTESIS '!$F28*12,'HIPOTESIS '!$C28/('HIPOTESIS '!$F28*12),0) -> 0 | F8: =IF(F$4<='HIPOTESIS '!$F28*12,'HIPOTESIS '!$C28/('HIPOTESIS '!$F28*12),0) -> 0 | G8: =IF(G$4<='HIPOTESIS '!$F28*12,'HIPOTESIS '!$C28/('HIPOTESIS '!$F28*12),0) -> 0 | H8: =IF(H$4<='HIPOTESIS '!$F28*12,'HIPOTESIS '!$C28/('HIPOTESIS '!$F28*12),0) -> 0 | I8: =IF(I$4<='HIPOTESIS '!$F28*12,'HIPOTESIS '!$C28/('HIPOTESIS '!$F28*12),0) -> 0 | J8: =IF(J$4<='HIPOTESIS '!$F28*12,'HIPOTESIS '!$C28/('HIPOTESIS '!$F28*12),0) -> 0 | K8: =IF(K$4<='HIPOTESIS '!$F28*12,'HIPOTESIS '!$C28/('HIPOTESIS '!$F28*12),0) -> 0 | ... BK8: =IF(BK$4<='HIPOTESIS '!$F28*12,'HIPOTESIS '!$C28/('HIPOTESIS '!$F28*12),0) -> 0 | BP8: 4
B9: Otros inmobilizados intangibles | C9: 0 | D9: =IF(D$4<='HIPOTESIS '!$F29*12,'HIPOTESIS '!$C29/('HIPOTESIS '!$F29*12),0) -> 0 | E9: =IF(E$4<='HIPOTESIS '!$F29*12,'HIPOTESIS '!$C29/('HIPOTESIS '!$F29*12),0) -> 0 | F9: =IF(F$4<='HIPOTESIS '!$F29*12,'HIPOTESIS '!$C29/('HIPOTESIS '!$F29*12),0) -> 0 | G9: =IF(G$4<='HIPOTESIS '!$F29*12,'HIPOTESIS '!$C29/('HIPOTESIS '!$F29*12),0) -> 0 | H9: =IF(H$4<='HIPOTESIS '!$F29*12,'HIPOTESIS '!$C29/('HIPOTESIS '!$F29*12),0) -> 0 | I9: =IF(I$4<='HIPOTESIS '!$F29*12,'HIPOTESIS '!$C29/('HIPOTESIS '!$F29*12),0) -> 0 | J9: =IF(J$4<='HIPOTESIS '!$F29*12,'HIPOTESIS '!$C29/('HIPOTESIS '!$F29*12),0) -> 0 | K9: =IF(K$4<='HIPOTESIS '!$F29*12,'HIPOTESIS '!$C29/('HIPOTESIS '!$F29*12),0) -> 0 | ... BK9: =IF(BK$4<='HIPOTESIS '!$F29*12,'HIPOTESIS '!$C29/('HIPOTESIS '!$F29*12),0) -> 0 | BN9: 0 | BP9: 5
B10: Amortización inmobilizado material inicial | BN10: 2 | BP10: 6 | BQ10: -0.2
B11: Terrenos y construcciones | C11: 0 | D11: =IF(D$4<='HIPOTESIS '!$F31*12,'HIPOTESIS '!$C31/('HIPOTESIS '!$F31*12),0) -> 0 | E11: =IF(E$4<='HIPOTESIS '!$F31*12,'HIPOTESIS '!$C31/('HIPOTESIS '!$F31*12),0) -> 0 | F11: =IF(F$4<='HIPOTESIS '!$F31*12,'HIPOTESIS '!$C31/('HIPOTESIS '!$F31*12),0) -> 0 | G11: =IF(G$4<='HIPOTESIS '!$F31*12,'HIPOTESIS '!$C31/('HIPOTESIS '!$F31*12),0) -> 0 | H11: =IF(H$4<='HIPOTESIS '!$F31*12,'HIPOTESIS '!$C31/('HIPOTESIS '!$F31*12),0) -> 0 | I11: =IF(I$4<='HIPOTESIS '!$F31*12,'HIPOTESIS '!$C31/('HIPOTESIS '!$F31*12),0) -> 0 | J11: =IF(J$4<='HIPOTESIS '!$F31*12,'HIPOTESIS '!$C31/('HIPOTESIS '!$F31*12),0) -> 0 | K11: =IF(K$4<='HIPOTESIS '!$F31*12,'HIPOTESIS '!$C31/('HIPOTESIS '!$F31*12),0) -> 0 | ... BK11: =IF(BK$4<='HIPOTESIS '!$F31*12,'HIPOTESIS '!$C31/('HIPOTESIS '!$F31*12),0) -> 0 | BN11: 4 | BP11: 7 | BQ11: -0.1
B12: Instalaciones | C12: 0 | D12: =IF(D$4<='HIPOTESIS '!$F32*12,'HIPOTESIS '!$C32/('HIPOTESIS '!$F32*12),0) -> 0 | E12: =IF(E$4<='HIPOTESIS '!$F32*12,'HIPOTESIS '!$C32/('HIPOTESIS '!$F32*12),0) -> 0 | F12: =IF(F$4<='HIPOTESIS '!$F32*12,'HIPOTESIS '!$C32/('HIPOTESIS '!$F32*12),0) -> 0 | G12: =IF(G$4<='HIPOTESIS '!$F32*12,'HIPOTESIS '!$C32/('HIPOTESIS '!$F32*12),0) -> 0 | H12: =IF(H$4<='HIPOTESIS '!$F32*12,'HIPOTESIS '!$C32/('HIPOTESIS '!$F32*12),0) -> 0 | I12: =IF(I$4<='HIPOTESIS '!$F32*12,'HIPOTESIS '!$C32/('HIPOTESIS '!$F32*12),0) -> 0 | J12: =IF(J$4<='HIPOTESIS '!$F32*12,'HIPOTESIS '!$C32/('HIPOTESIS '!$F32*12),0) -> 0 | K12: =IF(K$4<='HIPOTESIS '!$F32*12,'HIPOTESIS '!$C32/('HIPOTESIS '!$F32*12),0) -> 0 | ... BK12: =IF(BK$4<='HIPOTESIS '!$F32*12,'HIPOTESIS '!$C32/('HIPOTESIS '!$F32*12),0) -> 0 | BN12: 6 | BP12: 8 | BQ12: -0.09
B13: Maquinaria | C13: 0 | D13: =IF(D$4<='HIPOTESIS '!$F33*12,'HIPOTESIS '!$C33/('HIPOTESIS '!$F33*12),0) -> 0 | E13: =IF(E$4<='HIPOTESIS '!$F33*12,'HIPOTESIS '!$C33/('HIPOTESIS '!$F33*12),0) -> 0 | F13: =IF(F$4<='HIPOTESIS '!$F33*12,'HIPOTESIS '!$C33/('HIPOTESIS '!$F33*12),0) -> 0 | G13: =IF(G$4<='HIPOTESIS '!$F33*12,'HIPOTESIS '!$C33/('HIPOTESIS '!$F33*12),0) -> 0 | H13: =IF(H$4<='HIPOTESIS '!$F33*12,'HIPOTESIS '!$C33/('HIPOTESIS '!$F33*12),0) -> 0 | I13: =IF(I$4<='HIPOTESIS '!$F33*12,'HIPOTESIS '!$C33/('HIPOTESIS '!$F33*12),0) -> 0 | J13: =IF(J$4<='HIPOTESIS '!$F33*12,'HIPOTESIS '!$C33/('HIPOTESIS '!$F33*12),0) -> 0 | K13: =IF(K$4<='HIPOTESIS '!$F33*12,'HIPOTESIS '!$C33/('HIPOTESIS '!$F33*12),0) -> 0 | ... BK13: =IF(BK$4<='HIPOTESIS '!$F33*12,'HIPOTESIS '!$C33/('HIPOTESIS '!$F33*12),0) -> 0 | BN13: 8 | BP13: 9 | BQ13: -0.08
B14: Equipos para procesos de información( Ordenadores) | C14: 0 | D14: =IF(D$4<='HIPOTESIS '!$F34*12,'HIPOTESIS '!$C34/('HIPOTESIS '!$F34*12),0) -> 0 | E14: =IF(E$4<='HIPOTESIS '!$F34*12,'HIPOTESIS '!$C34/('HIPOTESIS '!$F34*12),0) -> 0 | F14: =IF(F$4<='HIPOTESIS '!$F34*12,'HIPOTESIS '!$C34/('HIPOTESIS '!$F34*12),0) -> 0 | G14: =IF(G$4<='HIPOTESIS '!$F34*12,'HIPOTESIS '!$C34/('HIPOTESIS '!$F34*12),0) -> 0 | H14: =IF(H$4<='HIPOTESIS '!$F34*12,'HIPOTESIS '!$C34/('HIPOTESIS '!$F34*12),0) -> 0 | I14: =IF(I$4<='HIPOTESIS '!$F34*12,'HIPOTESIS '!$C34/('HIPOTESIS '!$F34*12),0) -> 0 | J14: =IF(J$4<='HIPOTESIS '!$F34*12,'HIPOTESIS '!$C34/('HIPOTESIS '!$F34*12),0) -> 0 | K14: =IF(K$4<='HIPOTESIS '!$F34*12,'HIPOTESIS '!$C34/('HIPOTESIS '!$F34*12),0) -> 0 | ... BK14: =IF(BK$4<='HIPOTESIS '!$F34*12,'HIPOTESIS '!$C34/('HIPOTESIS '!$F34*12),0) -> 0 | BN14: 10 | BP14: 10 | BQ14: -0.07
B15: Mobiliario | C15: 0 | D15: =IF(D$4<='HIPOTESIS '!$F35*12,'HIPOTESIS '!$C35/('HIPOTESIS '!$F35*12),0) -> 0 | E15: =IF(E$4<='HIPOTESIS '!$F35*12,'HIPOTESIS '!$C35/('HIPOTESIS '!$F35*12),0) -> 0 | F15: =IF(F$4<='HIPOTESIS '!$F35*12,'HIPOTESIS '!$C35/('HIPOTESIS '!$F35*12),0) -> 0 | G15: =IF(G$4<='HIPOTESIS '!$F35*12,'HIPOTESIS '!$C35/('HIPOTESIS '!$F35*12),0) -> 0 | H15: =IF(H$4<='HIPOTESIS '!$F35*12,'HIPOTESIS '!$C35/('HIPOTESIS '!$F35*12),0) -> 0 | I15: =IF(I$4<='HIPOTESIS '!$F35*12,'HIPOTESIS '!$C35/('HIPOTESIS '!$F35*12),0) -> 0 | J15: =IF(J$4<='HIPOTESIS '!$F35*12,'HIPOTESIS '!$C35/('HIPOTESIS '!$F35*12),0) -> 0 | K15: =IF(K$4<='HIPOTESIS '!$F35*12,'HIPOTESIS '!$C35/('HIPOTESIS '!$F35*12),0) -> 0 | ... BK15: =IF(BK$4<='HIPOTESIS '!$F35*12,'HIPOTESIS '!$C35/('HIPOTESIS '!$F35*12),0) -> 0 | BN15: 12 | BP15: 11 | BQ15: -0.06
B16: Vehículos | C16: 0 | D16: =IF(D$4<='HIPOTESIS '!$F36*12,'HIPOTESIS '!$C36/('HIPOTESIS '!$F36*12),0) -> 0 | E16: =IF(E$4<='HIPOTESIS '!$F36*12,'HIPOTESIS '!$C36/('HIPOTESIS '!$F36*12),0) -> 0 | F16: =IF(F$4<='HIPOTESIS '!$F36*12,'HIPOTESIS '!$C36/('HIPOTESIS '!$F36*12),0) -> 0 | G16: =IF(G$4<='HIPOTESIS '!$F36*12,'HIPOTESIS '!$C36/('HIPOTESIS '!$F36*12),0) -> 0 | H16: =IF(H$4<='HIPOTESIS '!$F36*12,'HIPOTESIS '!$C36/('HIPOTESIS '!$F36*12),0) -> 0 | I16: =IF(I$4<='HIPOTESIS '!$F36*12,'HIPOTESIS '!$C36/('HIPOTESIS '!$F36*12),0) -> 0 | J16: =IF(J$4<='HIPOTESIS '!$F36*12,'HIPOTESIS '!$C36/('HIPOTESIS '!$F36*12),0) -> 0 | K16: =IF(K$4<='HIPOTESIS '!$F36*12,'HIPOTESIS '!$C36/('HIPOTESIS '!$F36*12),0) -> 0 | ... BK16: =IF(BK$4<='HIPOTESIS '!$F36*12,'HIPOTESIS '!$C36/('HIPOTESIS '!$F36*12),0) -> 0 | BN16: 14 | BP16: 12 | BQ16: -0.05
B17: Otros inmobilizados materiales | C17: 0 | D17: =IF(D$4<='HIPOTESIS '!$F37*12,'HIPOTESIS '!$C37/('HIPOTESIS '!$F37*12),0) -> 0 | E17: =IF(E$4<='HIPOTESIS '!$F37*12,'HIPOTESIS '!$C37/('HIPOTESIS '!$F37*12),0) -> 0 | F17: =IF(F$4<='HIPOTESIS '!$F37*12,'HIPOTESIS '!$C37/('HIPOTESIS '!$F37*12),0) -> 0 | G17: =IF(G$4<='HIPOTESIS '!$F37*12,'HIPOTESIS '!$C37/('HIPOTESIS '!$F37*12),0) -> 0 | H17: =IF(H$4<='HIPOTESIS '!$F37*12,'HIPOTESIS '!$C37/('HIPOTESIS '!$F37*12),0) -> 0 | I17: =IF(I$4<='HIPOTESIS '!$F37*12,'HIPOTESIS '!$C37/('HIPOTESIS '!$F37*12),0) -> 0 | J17: =IF(J$4<='HIPOTESIS '!$F37*12,'HIPOTESIS '!$C37/('HIPOTESIS '!$F37*12),0) -> 0 | K17: =IF(K$4<='HIPOTESIS '!$F37*12,'HIPOTESIS '!$C37/('HIPOTESIS '!$F37*12),0) -> 0 | ... BK17: =IF(BK$4<='HIPOTESIS '!$F37*12,'HIPOTESIS '!$C37/('HIPOTESIS '!$F37*12),0) -> 0 | BN17: 16 | BQ17: -0.04
B18: Amortización nuevas inversiones y activaciones | BN18: 18 | BP18: -0.2 | BQ18: -0.03
B19: Inversión 1 | C19: =IF(AND(C4>inicio_inv1,C4<=(final_inv1)),imp_inv1/(años_amortiz_inv1*12),0) -> 0 | D19: =IF(AND(D4>inicio_inv1,D4<=(final_inv1)),imp_inv1/(años_amortiz_inv1*12),0) -> 0 | E19: =IF(AND(E4>inicio_inv1,E4<=(final_inv1)),imp_inv1/(años_amortiz_inv1*12),0) -> 0 | F19: =IF(AND(F4>inicio_inv1,F4<=(final_inv1)),imp_inv1/(años_amortiz_inv1*12),0) -> 0 | G19: =IF(AND(G4>inicio_inv1,G4<=(final_inv1)),imp_inv1/(años_amortiz_inv1*12),0) -> 0 | H19: =IF(AND(H4>inicio_inv1,H4<=(final_inv1)),imp_inv1/(años_amortiz_inv1*12),0) -> 0 | I19: =IF(AND(I4>inicio_inv1,I4<=(final_inv1)),imp_inv1/(años_amortiz_inv1*12),0) -> 0 | J19: =IF(AND(J4>inicio_inv1,J4<=(final_inv1)),imp_inv1/(años_amortiz_inv1*12),0) -> 0 | ... BK19: =IF(AND(BK4>inicio_inv1,BK4<=(final_inv1)),imp_inv1/(años_amortiz_inv1*12),0) -> 0 | BN19: 20 | BO19: -0.3 | BP19: -0.1 | BQ19: -0.02
B20: Inversión 2 | C20: =IF(AND(C4>inicio_inv2,C4<=(final_inv2)),imp_inv2/(años_amortiz_inv2*12),0) -> 0 | D20: =IF(AND(D4>inicio_inv2,D4<=(final_inv2)),imp_inv2/(años_amortiz_inv2*12),0) -> 0 | E20: =IF(AND(E4>inicio_inv2,E4<=(final_inv2)),imp_inv2/(años_amortiz_inv2*12),0) -> 0 | F20: =IF(AND(F4>inicio_inv2,F4<=(final_inv2)),imp_inv2/(años_amortiz_inv2*12),0) -> 0 | G20: =IF(AND(G4>inicio_inv2,G4<=(final_inv2)),imp_inv2/(años_amortiz_inv2*12),0) -> 0 | H20: =IF(AND(H4>inicio_inv2,H4<=(final_inv2)),imp_inv2/(años_amortiz_inv2*12),0) -> 0 | I20: =IF(AND(I4>inicio_inv2,I4<=(final_inv2)),imp_inv2/(años_amortiz_inv2*12),0) -> 0 | J20: =IF(AND(J4>inicio_inv2,J4<=(final_inv2)),imp_inv2/(años_amortiz_inv2*12),0) -> 0 | ... BK20: =IF(AND(BK4>inicio_inv2,BK4<=(final_inv2)),imp_inv2/(años_amortiz_inv2*12),0) -> 0 | BO20: -0.2 | BP20: -0.08 | BQ20: -0.01
B21: Proyecto activación 1 | C21: =IF(AND(C4>inicio_amortiz_activ1,C4<=(final_amortiz_activ1)),imp_activacion1/(años_amortiz_activ1*12),0) -> 0 | D21: =IF(AND(D4>inicio_amortiz_activ1,D4<=(final_amortiz_activ1)),imp_activacion1/(años_amortiz_activ1*12),0) -> 0 | E21: =IF(AND(E4>inicio_amortiz_activ1,E4<=(final_amortiz_activ1)),imp_activacion1/(años_amortiz_activ1*12),0) -> 0 | F21: =IF(AND(F4>inicio_amortiz_activ1,F4<=(final_amortiz_activ1)),imp_activacion1/(años_amortiz_activ1*12),0) -> 0 | G21: =IF(AND(G4>inicio_amortiz_activ1,G4<=(final_amortiz_activ1)),imp_activacion1/(años_amortiz_activ1*12),0) -> 0 | H21: =IF(AND(H4>inicio_amortiz_activ1,H4<=(final_amortiz_activ1)),imp_activacion1/(años_amortiz_activ1*12),0) -> 0 | I21: =IF(AND(I4>inicio_amortiz_activ1,I4<=(final_amortiz_activ1)),imp_activacion1/(años_amortiz_activ1*12),0) -> 0 | J21: =IF(AND(J4>inicio_amortiz_activ1,J4<=(final_amortiz_activ1)),imp_activacion1/(años_amortiz_activ1*12),0) -> 0 | ... BK21: =IF(AND(BK4>inicio_amortiz_activ1,BK4<=(final_amortiz_activ1)),imp_activacion1/(años_amortiz_activ1*12),0) -> 0 | BO21: -0.15 | BP21: -0.06 | BQ21: 0
B22: Proyecto activación2 | C22: =IF(AND(C4>inicio_amortiz_activ2,C4<=(final_amortiz_activ2)),imp_activacion2/(años_amortiz_activ2*12),0) -> 0 | D22: =IF(AND(D4>inicio_amortiz_activ2,D4<=(final_amortiz_activ2)),imp_activacion2/(años_amortiz_activ2*12),0) -> 0 | E22: =IF(AND(E4>inicio_amortiz_activ2,E4<=(final_amortiz_activ2)),imp_activacion2/(años_amortiz_activ2*12),0) -> 0 | F22: =IF(AND(F4>inicio_amortiz_activ2,F4<=(final_amortiz_activ2)),imp_activacion2/(años_amortiz_activ2*12),0) -> 0 | G22: =IF(AND(G4>inicio_amortiz_activ2,G4<=(final_amortiz_activ2)),imp_activacion2/(años_amortiz_activ2*12),0) -> 0 | H22: =IF(AND(H4>inicio_amortiz_activ2,H4<=(final_amortiz_activ2)),imp_activacion2/(años_amortiz_activ2*12),0) -> 0 | I22: =IF(AND(I4>inicio_amortiz_activ2,I4<=(final_amortiz_activ2)),imp_activacion2/(años_amortiz_activ2*12),0) -> 0 | J22: =IF(AND(J4>inicio_amortiz_activ2,J4<=(final_amortiz_activ2)),imp_activacion2/(años_amortiz_activ2*12),0) -> 0 | ... BK22: =IF(AND(BK4>inicio_amortiz_activ2,BK4<=(final_amortiz_activ2)),imp_activacion2/(años_amortiz_activ2*12),0) -> 0 | BO22: -0.1 | BP22: -0.04 | BQ22: 0.01
B23: TOTAL amortizaciones | C23: =SUM(C6:C22) -> 0 | D23: =SUM(D6:D22) -> 0 | E23: =SUM(E6:E22) -> 0 | F23: =SUM(F6:F22) -> 0 | G23: =SUM(G6:G22) -> 0 | H23: =SUM(H6:H22) -> 0 | I23: =SUM(I6:I22) -> 0 | J23: =SUM(J6:J22) -> 0 | ... BK23: =SUM(BK6:BK22) -> 0 | BO23: -0.05 | BP23: -0.02 | BQ23: 0.02
B24: Amortización de las subvenciones de capital (por inversiones y activaciones) | BO24: 0 | BP24: 0 | BQ24: 0.03
B25: Subvención inversión 1 | C25: =IF(AND(C4>inicio_subv_inv1,C4<=(final_subv_inv1)),imp_subv_inv1/(años_amortiz_inv1*12),0) -> 0 | D25: =IF(AND(D4>inicio_subv_inv1,D4<=(final_subv_inv1)),imp_subv_inv1/(años_amortiz_inv1*12),0) -> 0 | E25: =IF(AND(E4>inicio_subv_inv1,E4<=(final_subv_inv1)),imp_subv_inv1/(años_amortiz_inv1*12),0) -> 0 | F25: =IF(AND(F4>inicio_subv_inv1,F4<=(final_subv_inv1)),imp_subv_inv1/(años_amortiz_inv1*12),0) -> 0 | G25: =IF(AND(G4>inicio_subv_inv1,G4<=(final_subv_inv1)),imp_subv_inv1/(años_amortiz_inv1*12),0) -> 0 | H25: =IF(AND(H4>inicio_subv_inv1,H4<=(final_subv_inv1)),imp_subv_inv1/(años_amortiz_inv1*12),0) -> 0 | I25: =IF(AND(I4>inicio_subv_inv1,I4<=(final_subv_inv1)),imp_subv_inv1/(años_amortiz_inv1*12),0) -> 0 | J25: =IF(AND(J4>inicio_subv_inv1,J4<=(final_subv_inv1)),imp_subv_inv1/(años_amortiz_inv1*12),0) -> 0 | ... BK25: =IF(AND(BK4>inicio_subv_inv1,BK4<=(final_subv_inv1)),imp_subv_inv1/(años_amortiz_inv1*12),0) -> 0 | BO25: 0.05 | BP25: 0.02 | BQ25: 0.04
B26: Subvención inversión 2 | C26: =IF(AND(C4>inicio_subv_inv2,C4<=(final_subv_inv2)),imp_subv_inv2/(años_amortiz_inv2*12),0) -> 0 | D26: =IF(AND(D4>inicio_subv_inv2,D4<=(final_subv_inv2)),imp_subv_inv2/(años_amortiz_inv2*12),0) -> 0 | E26: =IF(AND(E4>inicio_subv_inv2,E4<=(final_subv_inv2)),imp_subv_inv2/(años_amortiz_inv2*12),0) -> 0 | F26: =IF(AND(F4>inicio_subv_inv2,F4<=(final_subv_inv2)),imp_subv_inv2/(años_amortiz_inv2*12),0) -> 0 | G26: =IF(AND(G4>inicio_subv_inv2,G4<=(final_subv_inv2)),imp_subv_inv2/(años_amortiz_inv2*12),0) -> 0 | H26: =IF(AND(H4>inicio_subv_inv2,H4<=(final_subv_inv2)),imp_subv_inv2/(años_amortiz_inv2*12),0) -> 0 | I26: =IF(AND(I4>inicio_subv_inv2,I4<=(final_subv_inv2)),imp_subv_inv2/(años_amortiz_inv2*12),0) -> 0 | J26: =IF(AND(J4>inicio_subv_inv2,J4<=(final_subv_inv2)),imp_subv_inv2/(años_amortiz_inv2*12),0) -> 0 | ... BK26: =IF(AND(BK4>inicio_subv_inv2,BK4<=(final_subv_inv2)),imp_subv_inv2/(años_amortiz_inv2*12),0) -> 0 | BO26: 0.1 | BP26: 0.04 | BQ26: 0.05
B27: Subvención activación 1 | C27: =IF(AND(C4>inicio_amortiz_activ1,C4<=(final_amortiz_activ1)),imp_subv_activ1/(años_amortiz_activ1*12),0) -> 0 | D27: =IF(AND(D4>inicio_amortiz_activ1,D4<=(final_amortiz_activ1)),imp_subv_activ1/(años_amortiz_activ1*12),0) -> 0 | E27: =IF(AND(E4>inicio_amortiz_activ1,E4<=(final_amortiz_activ1)),imp_subv_activ1/(años_amortiz_activ1*12),0) -> 0 | F27: =IF(AND(F4>inicio_amortiz_activ1,F4<=(final_amortiz_activ1)),imp_subv_activ1/(años_amortiz_activ1*12),0) -> 0 | G27: =IF(AND(G4>inicio_amortiz_activ1,G4<=(final_amortiz_activ1)),imp_subv_activ1/(años_amortiz_activ1*12),0) -> 0 | H27: =IF(AND(H4>inicio_amortiz_activ1,H4<=(final_amortiz_activ1)),imp_subv_activ1/(años_amortiz_activ1*12),0) -> 0 | I27: =IF(AND(I4>inicio_amortiz_activ1,I4<=(final_amortiz_activ1)),imp_subv_activ1/(años_amortiz_activ1*12),0) -> 0 | J27: =IF(AND(J4>inicio_amortiz_activ1,J4<=(final_amortiz_activ1)),imp_subv_activ1/(años_amortiz_activ1*12),0) -> 0 | ... BK27: =IF(AND(BK4>inicio_amortiz_activ1,BK4<=(final_amortiz_activ1)),imp_subv_activ1/(años_amortiz_activ1*12),0) -> 0 | BO27: 0.15 | BP27: 0.06 | BQ27: 0.06
B28: Subvención activación 2 | C28: =IF(AND(C4>inicio_amortiz_activ2,C4<=(final_amortiz_activ2)),imp_subv_activ2/(años_amortiz_activ2*12),0) -> 0 | D28: =IF(AND(D4>inicio_amortiz_activ2,D4<=(final_amortiz_activ2)),imp_subv_activ2/(años_amortiz_activ2*12),0) -> 0 | E28: =IF(AND(E4>inicio_amortiz_activ2,E4<=(final_amortiz_activ2)),imp_subv_activ2/(años_amortiz_activ2*12),0) -> 0 | F28: =IF(AND(F4>inicio_amortiz_activ2,F4<=(final_amortiz_activ2)),imp_subv_activ2/(años_amortiz_activ2*12),0) -> 0 | G28: =IF(AND(G4>inicio_amortiz_activ2,G4<=(final_amortiz_activ2)),imp_subv_activ2/(años_amortiz_activ2*12),0) -> 0 | H28: =IF(AND(H4>inicio_amortiz_activ2,H4<=(final_amortiz_activ2)),imp_subv_activ2/(años_amortiz_activ2*12),0) -> 0 | I28: =IF(AND(I4>inicio_amortiz_activ2,I4<=(final_amortiz_activ2)),imp_subv_activ2/(años_amortiz_activ2*12),0) -> 0 | J28: =IF(AND(J4>inicio_amortiz_activ2,J4<=(final_amortiz_activ2)),imp_subv_activ2/(años_amortiz_activ2*12),0) -> 0 | ... BK28: =IF(AND(BK4>inicio_amortiz_activ2,BK4<=(final_amortiz_activ2)),imp_subv_activ2/(años_amortiz_activ2*12),0) -> 0 | BO28: 0.2 | BP28: 0.08 | BQ28: 0.07
B29: TOTAL imputación de subvenciones de capital | C29: =SUM(C25:C28) -> 0 | D29: =SUM(D25:D28) -> 0 | E29: =SUM(E25:E28) -> 0 | F29: =SUM(F25:F28) -> 0 | G29: =SUM(G25:G28) -> 0 | H29: =SUM(H25:H28) -> 0 | I29: =SUM(I25:I28) -> 0 | J29: =SUM(J25:J28) -> 0 | ... BK29: =SUM(BK25:BK28) -> 0 | BO29: 0.3 | BP29: 0.1 | BQ29: 0.08
BP30: 0.2 | BQ30: 0.09
B31: CUADRO DE ACTUALIZACIÓN DEL VALOR CONTABLE DE LOS ACTIVOS Y LAS SUBVENCIONES DE CAPITAL | BQ31: 0.1
C32: 0 | D32: 1 | E32: 2 | F32: 3 | G32: 4 | H32: 5 | I32: 6 | J32: 7 | K32: 8 | L32: 9 | M32: 10 | N32: 11 | O32: 12 | P32: 13 | Q32: 14 | R32: 15 | S32: 16 | T32: 17 | U32: 18 | V32: 19 | W32: 20 | X32: 21 | Y32: 22 | Z32: 23 | AA32: 24 | AB32: 25 | AC32: 26 | AD32: 27 | AE32: 28 | AF32: 29 | AG32: 30 | AH32: 31 | AI32: 32 | AJ32: 33 | AK32: 34 | AL32: 35 | AM32: 36 | AN32: 37 | AO32: 38 | AP32: 39 | AQ32: 40 | AR32: 41 | AS32: 42 | AT32: 43 | AU32: 44 | AV32: 45 | AW32: 46 | AX32: 47 | AY32: 48 | AZ32: 49 | BA32: 50 | BB32: 51 | BC32: 52 | BD32: 53 | BE32: 54 | BF32: 55 | BG32: 56 | BH32: 57 | BI32: 58 | BJ32: 59 | BK32: 60 | BQ32: 0.2
B33: Valor del inmobilizado intangible inicial
B34: Investigación y desarrollo | C34: ='HIPOTESIS '!C26 -> 0 | D34: =C34-D6 -> 0 | E34: =D34-E6 -> 0 | F34: =E34-F6 -> 0 | G34: =F34-G6 -> 0 | H34: =G34-H6 -> 0 | I34: =H34-I6 -> 0 | J34: =I34-J6 -> 0 | K34: =J34-K6 -> 0 | ... BK34: =BJ34-BK6 -> 0
B35: Patentes y marcas | C35: ='HIPOTESIS '!C27 -> 0 | D35: =C35-D7 -> 0 | E35: =D35-E7 -> 0 | F35: =E35-F7 -> 0 | G35: =F35-G7 -> 0 | H35: =G35-H7 -> 0 | I35: =H35-I7 -> 0 | J35: =I35-J7 -> 0 | K35: =J35-K7 -> 0 | ... BK35: =BJ35-BK7 -> 0
B36: Aplicaciones informáticas | C36: ='HIPOTESIS '!C28 -> 0 | D36: =C36-D8 -> 0 | E36: =D36-E8 -> 0 | F36: =E36-F8 -> 0 | G36: =F36-G8 -> 0 | H36: =G36-H8 -> 0 | I36: =H36-I8 -> 0 | J36: =I36-J8 -> 0 | K36: =J36-K8 -> 0 | ... BK36: =BJ36-BK8 -> 0
B37: Otros inmobilizados intangibles | C37: ='HIPOTESIS '!C29 -> 0 | D37: =C37-D9 -> 0 | E37: =D37-E9 -> 0 | F37: =E37-F9 -> 0 | G37: =F37-G9 -> 0 | H37: =G37-H9 -> 0 | I37: =H37-I9 -> 0 | J37: =I37-J9 -> 0 | K37: =J37-K9 -> 0 | ... BK37: =BJ37-BK9 -> 0
B38: Valor del inmobilizado material inicial
B39: Terrenos y construcciones | C39: ='HIPOTESIS '!C31 -> 0 | D39: =C39-D11 -> 0 | E39: =D39-E11 -> 0 | F39: =E39-F11 -> 0 | G39: =F39-G11 -> 0 | H39: =G39-H11 -> 0 | I39: =H39-I11 -> 0 | J39: =I39-J11 -> 0 | K39: =J39-K11 -> 0 | ... BK39: =BJ39-BK11 -> 0
B40: Instalaciones | C40: ='HIPOTESIS '!C32 -> 0 | D40: =C40-D12 -> 0 | E40: =D40-E12 -> 0 | F40: =E40-F12 -> 0 | G40: =F40-G12 -> 0 | H40: =G40-H12 -> 0 | I40: =H40-I12 -> 0 | J40: =I40-J12 -> 0 | K40: =J40-K12 -> 0 | ... BK40: =BJ40-BK12 -> 0
...

Sheet RESULTADOS
B1: www.toolboardcanvas.com
A2: Parte III: RESULTADOS PREVISIONALES
AU3: =SUM(AN7:AU7) -> 0 | AW3: =AW15+AW16+AW18+AW21 -> 0 | AX3: =AW3/0.3 -> 0
C4: AÑOS | O4: MES 0 | P4: MESES AÑO 1 | AB4: MESES AÑO 2 | AN4: MESES AÑO 3 | AZ4: MESES AÑO 4 | BL4: MESES AÑO 5
A5: A | B5: CUENTA DE RESULTADOS (P&L) | C5: AÑO 0 | D5: % | E5: AÑO 1 | F5: % | G5: AÑO 2 | H5: % | I5: AÑO 3 | J5: % | K5: AÑO 4 | L5: % | M5: AÑO 5 | N5: % | O5: 0 | P5: 1 | Q5: 2 | R5: 3 | S5: 4 | T5: 5 | U5: 6 | V5: 7 | W5: 8 | X5: 9 | Y5: 10 | Z5: 11 | AA5: 12 | AB5: 13 | AC5: 14 | AD5: 15 | AE5: 16 | AF5: 17 | AG5: 18 | AH5: 19 | AI5: 20 | AJ5: 21 | AK5: 22 | AL5: 23 | AM5: 24 | AN5: 25 | AO5: 26 | AP5: 27 | AQ5: 28 | AR5: 29 | AS5: 30 | AT5: 31 | AU5: 32 | AV5: 33 | AW5: 34 | AX5: 35 | AY5: 36 | AZ5: 37 | BA5: 38 | BB5: 39 | BC5: 40 | BD5: 41 | BE5: 42 | BF5: 43 | BG5: 44 | BH5: 45 | BI5: 46 | BJ5: 47 | BK5: 48 | BL5: 49 | BM5: 50 | BN5: 51 | BO5: 52 | BP5: 53 | BQ5: 54 | BR5: 55 | BS5: 56 | BT5: 57 | BU5: 58 | BV5: 59 | BW5: 60
B6: INGRESOS | C6: =C7+C8 -> 0 | E6: =E7+E8 -> 0 | F6: =IFERROR(E6/E6,"-") -> - | G6: =G7+G8 -> 0 | H6: =IFERROR(G6/G6,"-") -> - | I6: =I7+I8 -> 0 | J6: =IFERROR(I6/I6,"-") -> - | K6: =K7+K8 -> 0 | L6: =IFERROR(K6/K6,"-") -> - | M6: =M7+M8 -> 0 | N6: =IFERROR(M6/M6,"-") -> - | O6: 0 | P6: =P7+P8 -> 0 | Q6: =Q7+Q8 -> 0 | R6: =R7+R8 -> 0 | S6: =S7+S8 -> 0 | T6: =T7+T8 -> 0 | U6: =U7+U8 -> 0 | V6: =V7+V8 -> 0 | W6: =W7+W8 -> 0 | ... BW6: =BW7+BW8 -> 0
B7: Ventas totales | C7: =O7 -> 0 | E7: =SUM(P7:AA7) -> 0 | G7: =SUM(AB7:AM7) -> 0 | I7: =SUM(AN7:AY7) -> 0 | K7: =SUM(AZ7:BK7) -> 0 | M7: =SUM(BL7:BW7) -> 0 | O7: 0 | P7: ='HIPOTESIS '!D146+'HIPOTESIS '!D153+'HIPOTESIS '!D160 -> 0 | Q7: ='HIPOTESIS '!E146+'HIPOTESIS '!E153+'HIPOTESIS '!E160 -> 0 | R7: ='HIPOTESIS '!F146+'HIPOTESIS '!F153+'HIPOTESIS '!F160 -> 0 | S7: ='HIPOTESIS '!G146+'HIPOTESIS '!G153+'HIPOTESIS '!G160 -> 0 | T7: ='HIPOTESIS '!H146+'HIPOTESIS '!H153+'HIPOTESIS '!H160 -> 0 | U7: ='HIPOTESIS '!I146+'HIPOTESIS '!I153+'HIPOTESIS '!I160 -> 0 | V7: ='HIPOTESIS '!J146+'HIPOTESIS '!J153+'HIPOTESIS '!J160 -> 0 | W7: ='HIPOTESIS '!K146+'HIPOTESIS '!K153+'HIPOTESIS '!K160 -> 0 | ... BW7: ='HIPOTESIS '!BK146+'HIPOTESIS '!BK153+'HIPOTESIS '!BK160 -> 0
B8: Subvenciones de explotación | C8: =O8 -> 0 | E8: =SUM(P8:AA8) -> 0 | G8: =SUM(AB8:AM8) -> 0 | I8: =SUM(AN8:AY8) -> 0 | K8: =SUM(AZ8:BK8) -> 0 | M8: =SUM(BL8:BW8) -> 0 | O8: 0 | P8: ='HIPOTESIS '!D164 -> 0 | Q8: ='HIPOTESIS '!E164 -> 0 | R8: ='HIPOTESIS '!F164 -> 0 | S8: ='HIPOTESIS '!G164 -> 0 | T8: ='HIPOTESIS '!H164 -> 0 | U8: ='HIPOTESIS '!I164 -> 0 | V8: ='HIPOTESIS '!J164 -> 0 | W8: ='HIPOTESIS '!K164 -> 0 | ... BW8: ='HIPOTESIS '!BK164 -> 0
B10: COSTES DE LAS VENTAS
B11: Costes variables de las ventas | C11: =O11 -> 0 | E11: =SUM(P11:AA11) -> 0 | F11: =IFERROR((E11)/E7,"-") -> - | G11: =SUM(AB11:AM11) -> 0 | H11: =IFERROR((G11)/G7,"-") -> - | I11: =SUM(AN11:AY11) -> 0 | J11: =IFERROR((I11)/I7,"-") -> - | K11: =SUM(AZ11:BK11) -> 0 | L11: =IFERROR((K11)/K7,"-") -> - | M11: =SUM(BL11:BW11) -> 0 | N11: =IFERROR((M11)/M7,"-") -> - | O11: 0 | P11: ='HIPOTESIS '!D148+'HIPOTESIS '!D155+'HIPOTESIS '!D162 -> 0 | Q11: ='HIPOTESIS '!E148+'HIPOTESIS '!E155+'HIPOTESIS '!E162 -> 0 | R11: ='HIPOTESIS '!F148+'HIPOTESIS '!F155+'HIPOTESIS '!F162 -> 0 | S11: ='HIPOTESIS '!G148+'HIPOTESIS '!G155+'HIPOTESIS '!G162 -> 0 | T11: ='HIPOTESIS '!H148+'HIPOTESIS '!H155+'HIPOTESIS '!H162 -> 0 | U11: ='HIPOTESIS '!I148+'HIPOTESIS '!I155+'HIPOTESIS '!I162 -> 0 | V11: ='HIPOTESIS '!J148+'HIPOTESIS '!J155+'HIPOTESIS '!J162 -> 0 | W11: ='HIPOTESIS '!K148+'HIPOTESIS '!K155+'HIPOTESIS '!K162 -> 0 | ... BW11: ='HIPOTESIS '!BK148+'HIPOTESIS '!BK155+'HIPOTESIS '!BK162 -> 0
B12: Margen comercial | C12: =C7+C8-C11 -> 0 | E12: =E7+E8-E11 -> 0 | F12: =IFERROR(E12/E6,"-") -> - | G12: =G7+G8-G11 -> 0 | H12: =IFERROR(G12/G6,"-") -> - | I12: =I7+I8-I11 -> 0 | J12: =IFERROR(I12/I6,"-") -> - | K12: =K7+K8-K11 -> 0 | L12: =IFERROR(K12/K6,"-") -> - | M12: =M7+M8-M11 -> 0 | N12: =IFERROR(M12/M6,"-") -> - | O12: =O7+O8-O11 -> 0 | P12: =P7+P8-P11 -> 0 | Q12: =Q7+Q8-Q11 -> 0 | R12: =R7+R8-R11 -> 0 | S12: =S7+S8-S11 -> 0 | T12: =T7+T8-T11 -> 0 | U12: =U7+U8-U11 -> 0 | V12: =V7+V8-V11 -> 0 | ... BW12: =BW7+BW8-BW11 -> 0
B13: OTROS INGRESOS Y GASTOS
B14: Ingresos por trabajos para el propio activo | C14: =O14 -> 0 | E14: =SUM(P14:AA14) -> 0 | G14: =SUM(AB14:AM14) -> 0 | I14: =SUM(AN14:AY14) -> 0 | K14: =SUM(AZ14:BK14) -> 0 | M14: =SUM(BL14:BW14) -> 0 | O14: =IF(AND(O5>=inicio_trabaj_activacion1,O5<=final_trabaj_activacion1),imp_mensual_trabajo_activ1,0)+IF(AND(O5>=inicio_trabaj_activacion2,O5<=final_trabaj_activacion2),imp_mensual_trabajo_activ2,0) -> 0 | P14: =IF(AND(P5>=inicio_trabaj_activacion1,P5<=final_trabaj_activacion1),imp_mensual_trabajo_activ1,0)+IF(AND(P5>=inicio_trabaj_activacion2,P5<=final_trabaj_activacion2),imp_mensual_trabajo_activ2,0) -> 0 | Q14: =IF(AND(Q5>=inicio_trabaj_activacion1,Q5<=final_trabaj_activacion1),imp_mensual_trabajo_activ1,0)+IF(AND(Q5>=inicio_trabaj_activacion2,Q5<=final_trabaj_activacion2),imp_mensual_trabajo_activ2,0) -> 0 | R14: =IF(AND(R5>=inicio_trabaj_activacion1,R5<=final_trabaj_activacion1),imp_mensual_trabajo_activ1,0)+IF(AND(R5>=inicio_trabaj_activacion2,R5<=final_trabaj_activacion2),imp_mensual_trabajo_activ2,0) -> 0 | S14: =IF(AND(S5>=inicio_trabaj_activacion1,S5<=final_trabaj_activacion1),imp_mensual_trabajo_activ1,0)+IF(AND(S5>=inicio_trabaj_activacion2,S5<=final_trabaj_activacion2),imp_mensual_trabajo_activ2,0) -> 0 | T14: =IF(AND(T5>=inicio_trabaj_activacion1,T5<=final_trabaj_activacion1),imp_mensual_trabajo_activ1,0)+IF(AND(T5>=inicio_trabaj_activacion2,T5<=final_trabaj_activacion2),imp_mensual_trabajo_activ2,0) -> 0 | U14: =IF(AND(U5>=inicio_trabaj_activacion1,U5<=final_trabaj_activacion1),imp_mensual_trabajo_activ1,0)+IF(AND(U5>=inicio_trabaj_activacion2,U5<=final_trabaj_activacion2),imp_mensual_trabajo_activ2,0) -> 0 | V14: =IF(AND(V5>=inicio_trabaj_activacion1,V5<=final_trabaj_activacion1),imp_mensual_trabajo_activ1,0)+IF(AND(V5>=inicio_trabaj_activacion2,V5<=final_trabaj_activacion2),imp_mensual_trabajo_activ2,0) -> 0 | ... BW14: =IF(AND(BW5>=inicio_trabaj_activacion1,BW5<=final_trabaj_activacion1),imp_mensual_trabajo_activ1,0)+IF(AND(BW5>=inicio_trabaj_activacion2,BW5<=final_trabaj_activacion2),imp_mensual_trabajo_activ2,0) -> 0
B15: Gastos fijos por servicios exteriores | C15: =O15 -> 0 | E15: =SUM(P15:AA15) -> 0 | G15: =SUM(AB15:AM15) -> 0 | I15: =SUM(AN15:AY15) -> 0 | K15: =SUM(AZ15:BK15) -> 0 | M15: =SUM(BL15:BW15) -> 0 | O15: 0 | P15: ='HIPOTESIS '!$C$86/12 -> 0 | Q15: ='HIPOTESIS '!$C$86/12 -> 0 | R15: ='HIPOTESIS '!$C$86/12 -> 0 | S15: ='HIPOTESIS '!$C$86/12 -> 0 | T15: ='HIPOTESIS '!$C$86/12 -> 0 | U15: ='HIPOTESIS '!$C$86/12 -> 0 | V15: ='HIPOTESIS '!$C$86/12 -> 0 | W15: ='HIPOTESIS '!$C$86/12 -> 0 | ... AA15: ='HIPOTESIS '!$C$86/12 -> 0 | AB15: ='HIPOTESIS '!$F$86/12 -> 0 | AC15: ='HIPOTESIS '!$F$86/12 -> 0 | AD15: ='HIPOTESIS '!$F$86/12 -> 0 | AE15: ='HIPOTESIS '!$F$86/12 -> 0 | AF15: ='HIPOTESIS '!$F$86/12 -> 0 | AG15: ='HIPOTESIS '!$F$86/12 -> 0 | AH15: ='HIPOTESIS '!$F$86/12 -> 0 | AI15: ='HIPOTESIS '!$F$86/12 -> 0 | ... AM15: ='HIPOTESIS '!$F$86/12 -> 0 | AN15: ='HIPOTESIS '!$I$86/12 -> 0 | AO15: ='HIPOTESIS '!$I$86/12 -> 0 | AP15: ='HIPOTESIS '!$I$86/12 -> 0 | AQ15: ='HIPOTESIS '!$I$86/12 -> 0 | AR15: ='HIPOTESIS '!$I$86/12 -> 0 | AS15: ='HIPOTESIS '!$I$86/12 -> 0 | AT15: ='HIPOTESIS '!$I$86/12 -> 0 | AU15: ='HIPOTESIS '!$I$86/12 -> 0 | ... AY15: ='HIPOTESIS '!$I$86/12 -> 0 | AZ15: ='HIPOTESIS '!$L$86/12 -> 0 | BA15: ='HIPOTESIS '!$L$86/12 -> 0 | BB15: ='HIPOTESIS '!$L$86/12 -> 0 | BC15: ='HIPOTESIS '!$L$86/12 -> 0 | BD15: ='HIPOTESIS '!$L$86/12 -> 0 | BE15: ='HIPOTESIS '!$L$86/12 -> 0 | BF15: ='HIPOTESIS '!$L$86/12 -> 0 | BG15: ='HIPOTESIS '!$L$86/12 -> 0 | ... BK15: ='HIPOTESIS '!$L$86/12 -> 0 | BL15: ='HIPOTESIS '!$O$86/12 -> 0 | BM15: ='HIPOTESIS '!$O$86/12 -> 0 | BN15: ='HIPOTESIS '!$O$86/12 -> 0 | BO15: ='HIPOTESIS '!$O$86/12 -> 0 | BP15: ='HIPOTESIS '!$O$86/12 -> 0 | BQ15: ='HIPOTESIS '!$O$86/12 -> 0 | BR15: ='HIPOTESIS '!$O$86/12 -> 0 | BS15: ='HIPOTESIS '!$O$86/12 -> 0 | ... BW15: ='HIPOTESIS '!$O$86/12 -> 0
B16: Gastos fijos de nómina | C16: =O16 -> 0 | E16: =SUM(P16:AA16) -> 0 | G16: =SUM(AB16:AM16) -> 0 | I16: =SUM(AN16:AY16) -> 0 | K16: =SUM(AZ16:BK16) -> 0 | M16: =SUM(BL16:BW16) -> 0 | O16: ='C'!C167 -> 0 | P16: ='C'!D167 -> 0 | Q16: ='C'!E167 -> 0 | R16: ='C'!F167 -> 0 | S16: ='C'!G167 -> 0 | T16: ='C'!H167 -> 0 | U16: ='C'!I167 -> 0 | V16: ='C'!J167 -> 0 | ... BW16: ='C'!BK167 -> 0
B17: Margen EBITDA | C17: =C12+C14-C15-C16 -> 0 | E17: =E12+E14-E15-E16 -> 0 | F17: =IFERROR(E17/E6,"-") -> - | G17: =G12+G14-G15-G16 -> 0 | H17: =IFERROR(G17/G6,"-") -> - | I17: =I12+I14-I15-I16 -> 0 | J17: =IFERROR(I17/I6,"-") -> - | K17: =K12+K14-K15-K16 -> 0 | L17: =IFERROR(K17/K6,"-") -> - | M17: =M12+M14-M15-M16 -> 0 | N17: =IFERROR(M17/M6,"-") -> - | O17: =O12+O14-O15-O16 -> 0 | P17: =P12+P14-P15-P16 -> 0 | Q17: =Q12+Q14-Q15-Q16 -> 0 | R17: =R12+R14-R15-R16 -> 0 | S17: =S12+S14-S15-S16 -> 0 | T17: =T12+T14-T15-T16 -> 0 | U17: =U12+U14-U15-U16 -> 0 | V17: =V12+V14-V15-V16 -> 0 | ... BW17: =BW12+BW14-BW15-BW16 -> 0
B18: Amortizaciones y depreciaciones | C18: =O18 -> 0 | E18: =SUM(P18:AA18) -> 0 | G18: =SUM(AB18:AM18) -> 0 | I18: =SUM(AN18:AY18) -> 0 | K18: =SUM(AZ18:BK18) -> 0 | M18: =SUM(BL18:BW18) -> 0 | O18: ='C'!C23 -> 0 | P18: ='C'!D23 -> 0 | Q18: ='C'!E23 -> 0 | R18: ='C'!F23 -> 0 | S18: ='C'!G23 -> 0 | T18: ='C'!H23 -> 0 | U18: ='C'!I23 -> 0 | V18: ='C'!J23 -> 0 | ... BW18: ='C'!BK23 -> 0
B19: Imputación de subvenciones de capital | C19: =O19 -> 0 | E19: =SUM(P19:AA19) -> 0 | G19: =SUM(AB19:AM19) -> 0 | I19: =SUM(AN19:AY19) -> 0 | K19: =SUM(AZ19:BK19) -> 0 | M19: =SUM(BL19:BW19) -> 0 | O19: ='C'!C29 -> 0 | P19: ='C'!D29 -> 0 | Q19: ='C'!E29 -> 0 | R19: ='C'!F29 -> 0 | S19: ='C'!G29 -> 0 | T19: ='C'!H29 -> 0 | U19: ='C'!I29 -> 0 | V19: ='C'!J29 -> 0 | ... BW19: ='C'!BK29 -> 0
B20: Margen EBIT | C20: =C17-C18+C19 -> 0 | E20: =E17-E18+E19 -> 0 | F20: =IFERROR(E20/E6,"-") -> - | G20: =G17-G18+G19 -> 0 | H20: =IFERROR(G20/G6,"-") -> - | I20: =I17-I18+I19 -> 0 | J20: =IFERROR(I20/I6,"-") -> - | K20: =K17-K18+K19 -> 0 | L20: =IFERROR(K20/K6,"-") -> - | M20: =M17-M18+M19 -> 0 | N20: =IFERROR(M20/M6,"-") -> - | O20: =O17-O18+O19 -> 0 | P20: =P17-P18+P19 -> 0 | Q20: =Q17-Q18+Q19 -> 0 | R20: =R17-R18+R19 -> 0 | S20: =S17-S18+S19 -> 0 | T20: =T17-T18+T19 -> 0 | U20: =U17-U18+U19 -> 0 | V20: =V17-V18+V19 -> 0 | ... BW20: =BW17-BW18+BW19 -> 0
B21: Resultado financiero (gastos menos ingresos financieros) | C21: =O21 -> 0 | E21: =SUM(P21:AA21) -> 0 | G21: =SUM(AB21:AM21) -> 0 | I21: =SUM(AN21:AY21) -> 0 | K21: =SUM(AZ21:BK21) -> 0 | M21: =SUM(BL21:BW21) -> 0 | O21: ='C'!C73+'C'!C82 -> 0 | P21: ='C'!D73+'C'!D82+'HIPOTESIS '!$D70/12*O57+'C'!D89 -> 0 | Q21: ='C'!E73+'C'!E82+'HIPOTESIS '!$D70/12*P57+'C'!E89 -> 0 | R21: ='C'!F73+'C'!F82+'HIPOTESIS '!$D70/12*Q57+'C'!F89 -> 0 | S21: ='C'!G73+'C'!G82+'HIPOTESIS '!$D70/12*R57+'C'!G89 -> 0 | T21: ='C'!H73+'C'!H82+'HIPOTESIS '!$D70/12*S57+'C'!H89 -> 0 | U21: ='C'!I73+'C'!I82+'HIPOTESIS '!$D70/12*T57+'C'!I89 -> 0 | V21: ='C'!J73+'C'!J82+'HIPOTESIS '!$D70/12*U57+'C'!J89 -> 0 | W21: ='C'!K73+'C'!K82+'HIPOTESIS '!$D70/12*V57+'C'!K89 -> 0 | ... BW21: ='C'!BK73+'C'!BK82+'HIPOTESIS '!$D70/12*BV57+'C'!BK89 -> 0
B22: Margen EBT | C22: =C20-C21 -> 0 | E22: =E20-E21 -> 0 | F22: =IFERROR(E22/E6,"-") -> - | G22: =G20-G21 -> 0 | H22: =IFERROR(G22/G6,"-") -> - | I22: =I20-I21 -> 0 | J22: =IFERROR(I22/I6,"-") -> - | K22: =K20-K21 -> 0 | L22: =IFERROR(K22/K6,"-") -> - | M22: =M20-M21 -> 0 | N22: =IFERROR(M22/M6,"-") -> - | O22: =O20-O21 -> 0 | P22: =P20-P21 -> 0 | Q22: =Q20-Q21 -> 0 | R22: =R20-R21 -> 0 | S22: =S20-S21 -> 0 | T22: =T20-T21 -> 0 | U22: =U20-U21 -> 0 | V22: =V20-V21 -> 0 | ... BW22: =BW20-BW21 -> 0
B23: Impuesto de Sociedades | C23: =O23 -> 0 | E23: =SUM(P23:AA23) -> 0 | G23: =SUM(AB23:AM23) -> 0 | I23: =SUM(AN23:AY23) -> 0 | K23: =SUM(AZ23:BK23) -> 0 | M23: =SUM(BL23:BW23) -> 0 | O23: ='C'!C267 -> 0 | P23: ='C'!D267 -> 0 | Q23: ='C'!E267 -> 0 | R23: ='C'!F267 -> 0 | S23: ='C'!G267 -> 0 | T23: ='C'!H267 -> 0 | U23: ='C'!I267 -> 0 | V23: ='C'!J267 -> 0 | ... BW23: ='C'!BK267 -> 0
B24: RESULTADO (Margen de beneficio o pérdida) | C24: =C22-C23 -> 0 | E24: =E22-E23 -> 0 | F24: =IFERROR(E24/E6,"-") -> - | G24: =G22-G23 -> 0 | H24: =IFERROR(G24/G6,"-") -> - | I24: =I22-I23 -> 0 | J24: =IFERROR(I24/I6,"-") -> - | K24: =K22-K23 -> 0 | L24: =IFERROR(K24/K6,"-") -> - | M24: =M22-M23 -> 0 | N24: =IFERROR(M24/M6,"-") -> - | O24: =O22-O23 -> 0 | P24: =P22-P23 -> 0 | Q24: =Q22-Q23 -> 0 | R24: =R22-R23 -> 0 | S24: =S22-S23 -> 0 | T24: =T22-T23 -> 0 | U24: =U22-U23 -> 0 | V24: =V22-V23 -> 0 | ... BW24: =BW22-BW23 -> 0
B25: (RESULTADO acumulado en fondos propios) | C25: =C24 -> 0 | E25: =C25+E24 -> 0 | G25: =E25+G24 -> 0 | I25: =G25+I24 -> 0 | K25: =I25+K24 -> 0 | M25: =K25+M24 -> 0 | O25: =O24 -> 0 | P25: =O25+P24 -> 0 | Q25: =P25+Q24 -> 0 | R25: =Q25+R24 -> 0 | S25: =R25+S24 -> 0 | T25: =S25+T24 -> 0 | U25: =T25+U24 -> 0 | V25: =U25+V24 -> 0 | W25: =V25+W24 -> 0 | ... BW25: =BV25+BW24 -> 0
C26: =IF(OR(E14>E16,G14>G16,I14>I16,K14>K16,M14>M16), "¡Cuidado!. Los tabajos para el propio activo en un año (ingreso por menos gasto) no pueden ser superiores a la nómina de ese año pues se deben ejecutar internamente. ¡Revisa los datos para obtener una proyección realista!", "-") -> -
C28: AÑOS | O28: MES 0 | P28: MESES AÑO 1 | AB28: MESES AÑO 2 | AN28: MESES AÑO 3 | AZ28: MESES AÑO 4 | BL28: MESES AÑO 5
A29: B | B29: FLUJO DE TESORERÍA (Cash Flow) | C29: AÑO 0 | D29: % | E29: AÑO 1 | F29: % | G29: AÑO 2 | H29: % | I29: AÑO 3 | J29: % | K29: AÑO 4 | L29: % | M29: AÑO 5 | N29: % | O29: 0 | P29: 1 | Q29: 2 | R29: 3 | S29: 4 | T29: 5 | U29: 6 | V29: 7 | W29: 8 | X29: 9 | Y29: 10 | Z29: 11 | AA29: 12 | AB29: 13 | AC29: 14 | AD29: 15 | AE29: 16 | AF29: 17 | AG29: 18 | AH29: 19 | AI29: 20 | AJ29: 21 | AK29: 22 | AL29: 23 | AM29: 24 | AN29: 25 | AO29: 26 | AP29: 27 | AQ29: 28 | AR29: 29 | AS29: 30 | AT29: 31 | AU29: 32 | AV29: 33 | AW29: 34 | AX29: 35 | AY29: 36 | AZ29: 37 | BA29: 38 | BB29: 39 | BC29: 40 | BD29: 41 | BE29: 42 | BF29: 43 | BG29: 44 | BH29: 45 | BI29: 46 | BJ29: 47 | BK29: 48 | BL29: 49 | BM29: 50 | BN29: 51 | BO29: 52 | BP29: 53 | BQ29: 54 | BR29: 55 | BS29: 56 | BT29: 57 | BU29: 58 | BV29: 59 | BW29: 60
B30: OPERACIONES
B31: Cobros de clientes | C31: =O31 -> 0 | E31: =SUM(P31:AA31) -> 0 | G31: =SUM(AB31:AM31) -> 0 | I31: =SUM(AN31:AY31) -> 0 | K31: =SUM(AZ31:BK31) -> 0 | M31: =SUM(BL31:BW31) -> 0 | O31: ='C'!C96*(1+IVA_ventas)+'C'!C100*(1+IVA_ventas)+'C'!C104*(1+IVA_ventas) -> 0 | P31: ='C'!D96*(1+IVA_ventas)+'C'!D100*(1+IVA_ventas)+'C'!D104*(1+IVA_ventas) -> 0 | Q31: ='C'!E96*(1+IVA_ventas)+'C'!E100*(1+IVA_ventas)+'C'!E104*(1+IVA_ventas) -> 0 | R31: ='C'!F96*(1+IVA_ventas)+'C'!F100*(1+IVA_ventas)+'C'!F104*(1+IVA_ventas) -> 0 | S31: ='C'!G96*(1+IVA_ventas)+'C'!G100*(1+IVA_ventas)+'C'!G104*(1+IVA_ventas) -> 0 | T31: ='C'!H96*(1+IVA_ventas)+'C'!H100*(1+IVA_ventas)+'C'!H104*(1+IVA_ventas) -> 0 | U31: ='C'!I96*(1+IVA_ventas)+'C'!I100*(1+IVA_ventas)+'C'!I104*(1+IVA_ventas) -> 0 | V31: ='C'!J96*(1+IVA_ventas)+'C'!J100*(1+IVA_ventas)+'C'!J104*(1+IVA_ventas) -> 0 | ... BW31: ='C'!BK96*(1+IVA_ventas)+'C'!BK100*(1+IVA_ventas)+'C'!BK104*(1+IVA_ventas) -> 0
B32: Cobro de subvenciones de explotación | C32: =O32 -> 0 | E32: =SUM(P32:AA32) -> 0 | G32: =SUM(AB32:AM32) -> 0 | I32: =SUM(AN32:AY32) -> 0 | K32: =SUM(AZ32:BK32) -> 0 | M32: =SUM(BL32:BW32) -> 0 | O32: =O8 -> 0 | P32: =P8 -> 0 | Q32: =Q8 -> 0 | R32: =R8 -> 0 | S32: =S8 -> 0 | T32: =T8 -> 0 | U32: =U8 -> 0 | V32: =V8 -> 0 | ... BW32: =BW8 -> 0
B33: Pagos a proveedores (coste de las ventas) | C33: =O33 -> 0 | E33: =SUM(P33:AA33) -> 0 | G33: =SUM(AB33:AM33) -> 0 | I33: =SUM(AN33:AY33) -> 0 | K33: =SUM(AZ33:BK33) -> 0 | M33: =SUM(BL33:BW33) -> 0 | O33: =-'C'!C98*(1+IVA_compras)-'C'!C102*(1+IVA_compras)-'C'!C106*(1+IVA_compras) -> 0 | P33: =-'C'!D98*(1+IVA_compras)-'C'!D102*(1+IVA_compras)-'C'!D106*(1+IVA_compras) -> 0 | Q33: =-'C'!E98*(1+IVA_compras)-'C'!E102*(1+IVA_compras)-'C'!E106*(1+IVA_compras) -> 0 | R33: =-'C'!F98*(1+IVA_compras)-'C'!F102*(1+IVA_compras)-'C'!F106*(1+IVA_compras) -> 0 | S33: =-'C'!G98*(1+IVA_compras)-'C'!G102*(1+IVA_compras)-'C'!G106*(1+IVA_compras) -> 0 | T33: =-'C'!H98*(1+IVA_compras)-'C'!H102*(1+IVA_compras)-'C'!H106*(1+IVA_compras) -> 0 | U33: =-'C'!I98*(1+IVA_compras)-'C'!I102*(1+IVA_compras)-'C'!I106*(1+IVA_compras) -> 0 | V33: =-'C'!J98*(1+IVA_compras)-'C'!J102*(1+IVA_compras)-'C'!J106*(1+IVA_compras) -> 0 | ... BW33: =-'C'!BK98*(1+IVA_compras)-'C'!BK102*(1+IVA_compras)-'C'!BK106*(1+IVA_compras) -> 0
B34: Pagos gastos fijos por servicios exteriores (al contado) | C34: =O34 -> 0 | E34: =SUM(P34:AA34) -> 0 | G34: =SUM(AB34:AM34) -> 0 | I34: =SUM(AN34:AY34) -> 0 | K34: =SUM(AZ34:BK34) -> 0 | M34: =SUM(BL34:BW34) -> 0 | O34: =-O15*(1+IVA_compras) -> 0 | P34: =-P15*(1+IVA_compras) -> 0 | Q34: =-Q15*(1+IVA_compras) -> 0 | R34: =-R15*(1+IVA_compras) -> 0 | S34: =-S15*(1+IVA_compras) -> 0 | T34: =-T15*(1+IVA_compras) -> 0 | U34: =-U15*(1+IVA_compras) -> 0 | V34: =-V15*(1+IVA_compras) -> 0 | ... BW34: =-BW15*(1+IVA_compras) -> 0
B35: Pago al contado de la nómina | C35: =O35 -> 0 | E35: =SUM(P35:AA35) -> 0 | G35: =SUM(AB35:AM35) -> 0 | I35: =SUM(AN35:AY35) -> 0 | K35: =SUM(AZ35:BK35) -> 0 | M35: =SUM(BL35:BW35) -> 0 | O35: =-'C'!C203 -> 0 | P35: =-'C'!D203 -> 0 | Q35: =-'C'!E203 -> 0 | R35: =-'C'!F203 -> 0 | S35: =-'C'!G203 -> 0 | T35: =-'C'!H203 -> 0 | U35: =-'C'!I203 -> 0 | V35: =-'C'!J203 -> 0 | ... BW35: =-'C'!BK203 -> 0
B36: Pago del seguro social a TGSS | C36: =O36 -> 0 | E36: =SUM(P36:AA36) -> 0 | G36: =SUM(AB36:AM36) -> 0 | I36: =SUM(AN36:AY36) -> 0 | K36: =SUM(AZ36:BK36) -> 0 | M36: =SUM(BL36:BW36) -> 0 | O36: =-'C'!C252 -> 0 | P36: =-'C'!D252 -> 0 | Q36: =-'C'!E252 -> 0 | R36: =-'C'!F252 -> 0 | S36: =-'C'!G252 -> 0 | T36: =-'C'!H252 -> 0 | U36: =-'C'!I252 -> 0 | V36: =-'C'!J252 -> 0 | ... BW36: =-'C'!BK252 -> 0
B37: Pago intereses préstamos (al contado) + póliza | C37: =O37 -> 0 | E37: =SUM(P37:AA37) -> 0 | G37: =SUM(AB37:AM37) -> 0 | I37: =SUM(AN37:AY37) -> 0 | K37: =SUM(AZ37:BK37) -> 0 | M37: =SUM(BL37:BW37) -> 0 | O37: =-O21 -> 0 | P37: =-P21 -> 0 | Q37: =-Q21 -> 0 | R37: =-R21 -> 0 | S37: =-S21 -> 0 | T37: =-T21 -> 0 | U37: =-U21 -> 0 | V37: =-V21 -> 0 | ... BW37: =-BW21 -> 0
B38: Pago de las retenciones a hacienda (IRPF) | C38: =O38 -> 0 | E38: =SUM(P38:AA38) -> 0 | G38: =SUM(AB38:AM38) -> 0 | I38: =SUM(AN38:AY38) -> 0 | K38: =SUM(AZ38:BK38) -> 0 | M38: =SUM(BL38:BW38) -> 0 | O38: =-'C'!C247 -> 0 | P38: =-'C'!D247 -> 0 | Q38: =-'C'!E247 -> 0 | R38: =-'C'!F247 -> 0 | S38: =-'C'!G247 -> 0 | T38: =-'C'!H247 -> 0 | U38: =-'C'!I247 -> 0 | V38: =-'C'!J247 -> 0 | ... BW38: =-'C'!BK247 -> 0
B39: Pago del IVA a hacienda | C39: =O39 -> 0 | E39: =SUM(P39:AA39) -> 0 | G39: =SUM(AB39:AM39) -> 0 | I39: =SUM(AN39:AY39) -> 0 | K39: =SUM(AZ39:BK39) -> 0 | M39: =SUM(BL39:BW39) -> 0 | O39: =-'C'!C259 -> 0 | P39: =-'C'!D259 -> 0 | Q39: =-'C'!E259 -> 0 | R39: =-'C'!F259 -> 0 | S39: =-'C'!G259 -> 0 | T39: =-'C'!H259 -> 0 | U39: =-'C'!I259 -> 0 | V39: =-'C'!J259 -> 0 | ... BW39: =-'C'!BK259 -> 0
B40: Pago del IS a hacienda (del mes anterior) | C40: =O40 -> 0 | E40: =SUM(P40:AA40) -> 0 | G40: =SUM(AB40:AM40) -> 0 | I40: =SUM(AN40:AY40) -> 0 | K40: =SUM(AZ40:BK40) -> 0 | M40: =SUM(BL40:BW40) -> 0 | O40: 0 | P40: =-O23 -> 0 | Q40: =-P23 -> 0 | R40: =-Q23 -> 0 | S40: =-R23 -> 0 | T40: =-S23 -> 0 | U40: =-T23 -> 0 | V40: =-U23 -> 0 | W40: =-V23 -> 0 | ... BW40: =-BV23 -> 0
B41: CF operaciones | C41: =C31+C32-C33-C34-C35-C37-C40-C39 -> 0 | E41: =SUM(E31:E40) -> 0 | F41: =IFERROR(E41/E56,"-") -> 0 | G41: =SUM(G31:G40) -> 0 | H41: =IFERROR(G41/G56,"-") -> 0 | I41: =SUM(I31:I40) -> 0 | J41: =IFERROR(I41/I56,"-") -> 0 | K41: =SUM(K31:K40) -> 0 | L41: =IFERROR(K41/K56,"-") -> 0 | M41: =SUM(M31:M40) -> 0 | N41: =IFERROR(M41/M56,"-") -> 0 | O41: =SUM(O31:O40) -> 0 | P41: =SUM(P31:P40) -> 0 | Q41: =SUM(Q31:Q40) -> 0 | R41: =SUM(R31:R40) -> 0 | S41: =SUM(S31:S40) -> 0 | T41: =SUM(T31:T40) -> 0 | U41: =SUM(U31:U40) -> 0 | V41: =SUM(V31:V40) -> 0 | ... BW41: =SUM(BW31:BW40) -> 0
B42: INVERSIONES
...

Sheet ANALISIS 
A2: Parte IV: ANÁLISIS
A4: A | B4: ANÁLISIS FINANCIERO (re-funding)
B6: DISPONIBLE DE TESORERÍA | C6: AÑO 0 | D6: AÑO 1 | E6: AÑO 2 | F6: AÑO 3 | G6: AÑO 4 | H6: AÑO 5 | I6: DATO | J6: ¿REFINANCIACIÓN CON CAPITAL ? | K6: MES DE ENTRADA | L6: IMPORTE | M6: VALORACIÓN EMPRESA (PRE-MONEY) | N6: ACCIONES TOTALES EN CIRCULACIÓN | O6: VALOR MONETARIO POR ACCIÓN | P6: % SOCIEDAD PARA LOS NUEVOS SOCIOS | Q6: VALOR PARA LOS FUNDADORES | R6: OBSERVACIONES
B7: Déficit en el disponible de tesorería | C7: =IF(RESULTADOS!C56>0,0,RESULTADOS!C56) -> 0 | D7: =IF(RESULTADOS!E56>0,0,RESULTADOS!E56) -> 0 | E7: =IF(RESULTADOS!G56>0,0,RESULTADOS!G56) -> 0 | F7: =IF(RESULTADOS!I56>0,0,RESULTADOS!I56) -> 0 | G7: =IF(RESULTADOS!K56>0,0,RESULTADOS!K56) -> 0 | H7: =IF(RESULTADOS!M56>0,0,RESULTADOS!M56) -> 0 | J7: Capital inicial desembolsado por los fundadores | K7: ='HIPOTESIS '!C63 -> 0 | L7: ='HIPOTESIS '!D63 -> 1000 | M7: =L7 -> 1000 | N7: ='HIPOTESIS '!F63 -> 1000 | O7: =L7/N7 -> 1 | P7: 0 | Q7: =O7*N7 -> 1000 | R7: La valoración de empresa en el mes "n" es el valor que las partes acuerdan libremente. Es común que responda a una métrica comercial sobre la que se aplica un múltiplo (por ejemplo un múltiplo de ventas, clientes activos, margen EBITDA, ...). En futuras ampliaciones de capital se genera una prima de emisión como diferencia entre valor nominal y valor real acordado en la valoración. En función de la valoración empresa (pre-money, es decir justo antes de la ampliación) el porcentaje de empresa que toman los socios se calcula por la diferencia entre valor acciones antes y después. Es opcional realizar este cálculo, simplemente para observar el % que se cede en función de comos se "crea" valor. Esta cuestión responde al "dilema de la dilución del emprendedor" del libro "El Viaje del Emprendedor".
